Workbook

Sheet Proveedores
A1: Proveedor | B1: RUC | C1: %Detracción | D1: DíasPago
A2: Servicios Integrales Andinos SAC | B2: 20123456789 | C2: 0.1 | D2: 30
A3: Logística Sur SAC | B3: 20456789123 | C3: 0.12 | D3: 45
A4: Suministros Empresariales SAC | B4: 20567891234 | C4: 0 | D4: 30
A5: Consultoría Delta SRL | B5: 20345678912 | C5: 0.1 | D5: 30
A6: Mantenimiento Técnico Perú SAC | B6: 20678912345 | C6: 0.12 | D6: 15
A7: Distribuidora Alfa SAC | B7: 20198765432 | C7: 0 | D7: 30
A8: Servicios Generales Beta SAC | B8: 20432198765 | C8: 0.04 | D8: 30
A9: Transportes Lima Express SAC | B9: 20543219876 | C9: 0.04 | D9: 15
A10: Soluciones Informáticas SAC | B10: 20321987654 | C10: 0 | D10: 30
A11: Seguridad Integral Omega SAC | B11: 20654321987 | C11: 0.12 | D11: 30

Sheet Facturas
A1: FechaEmisión | B1: Proveedor | C1: NumFactura | D1: Base | E1: IGV | F1: Total | G1: ¿Detracción? | H1: %Detracción | I1: MontoDetracción | J1: FechaVencimiento
A2: 46002 | B2: Logística Sur SAC | C2: F01-000001 | D2: 2875.43 | E2: =D2*0.18 -> 517.5774 | F2: =D2+E2 -> 3393.0074 | G2: SI | H2: =VLOOKUP(B2,Proveedores!$A$2:$D$11,3,FALSE) -> 0.12 | I2: =IF(G2="SI",F2*H2,0) -> 407.16089 | J2: =A2+VLOOKUP(B2,Proveedores!$A$2:$D$11,4,FALSE) -> 46047
A3: 45970 | B3: Logística Sur SAC | C3: F03-000002 | D3: 2872.34 | E3: =D3*0.18 -> 517.0212 | F3: =D3+E3 -> 3389.3612 | G3: SI | H3: =VLOOKUP(B3,Proveedores!$A$2:$D$11,3,FALSE) -> 0.12 | I3: =IF(G3="SI",F3*H3,0) -> 406.72334 | J3: =A3+VLOOKUP(B3,Proveedores!$A$2:$D$11,4,FALSE) -> 46015
A4: 45999 | B4: Servicios Generales Beta SAC | C4: F01-000003 | D4: 384.29 | E4: =D4*0.18 -> 69.1722 | F4: =D4+E4 -> 453.4622 | G4: SI | H4: =VLOOKUP(B4,Proveedores!$A$2:$D$11,3,FALSE) -> 0.04 | I4: =IF(G4="SI",F4*H4,0) -> 18.138488 | J4: =A4+VLOOKUP(B4,Proveedores!$A$2:$D$11,4,FALSE) -> 46029
A5: 45994 | B5: Seguridad Integral Omega SAC | C5: F01-000004 | D5: 2244.36 | E5: =D5*0.18 -> 403.9848 | F5: =D5+E5 -> 2648.3448 | G5: NO | H5: =VLOOKUP(B5,Proveedores!$A$2:$D$11,3,FALSE) -> 0.12 | I5: =IF(G5="SI",F5*H5,0) -> 0 | J5: =A5+VLOOKUP(B5,Proveedores!$A$2:$D$11,4,FALSE) -> 46024
A6: 46006 | B6: Soluciones Informáticas SAC | C6: F02-000005 | D6: 1051.54 | E6: =D6*0.18 -> 189.2772 | F6: =D6+E6 -> 1240.8172 | G6: NO | H6: =VLOOKUP(B6,Proveedores!$A$2:$D$11,3,FALSE) -> 0 | I6: =IF(G6="SI",F6*H6,0) -> 0 | J6: =A6+VLOOKUP(B6,Proveedores!$A$2:$D$11,4,FALSE) -> 46036
A7: 45999 | B7: Mantenimiento Técnico Perú SAC | C7: F01-000006 | D7: 2935.83 | E7: =D7*0.18 -> 528.4494 | F7: =D7+E7 -> 3464.2794 | G7: SI | H7: =VLOOKUP(B7,Proveedores!$A$2:$D$11,3,FALSE) -> 0.12 | I7: =IF(G7="SI",F7*H7,0) -> 415.71353 | J7: =A7+VLOOKUP(B7,Proveedores!$A$2:$D$11,4,FALSE) -> 46014
A8: 45989 | B8: Distribuidora Alfa SAC | C8: F02-000007 | D8: 824.18 | E8: =D8*0.18 -> 148.3524 | F8: =D8+E8 -> 972.5324 | G8: NO | H8: =VLOOKUP(B8,Proveedores!$A$2:$D$11,3,FALSE) -> 0 | I8: =IF(G8="SI",F8*H8,0) -> 0 | J8: =A8+VLOOKUP(B8,Proveedores!$A$2:$D$11,4,FALSE) -> 46019
A9: 46010 | B9: Distribuidora Alfa SAC | C9: F01-000008 | D9: 604.61 | E9: =D9*0.18 -> 108.8298 | F9: =D9+E9 -> 713.4398 | G9: NO | H9: =VLOOKUP(B9,Proveedores!$A$2:$D$11,3,FALSE) -> 0 | I9: =IF(G9="SI",F9*H9,0) -> 0 | J9: =A9+VLOOKUP(B9,Proveedores!$A$2:$D$11,4,FALSE) -> 46040
A10: 45968 | B10: Distribuidora Alfa SAC | C10: F02-000009 | D10: 2393.04 | E10: =D10*0.18 -> 430.7472 | F10: =D10+E10 -> 2823.7872 | G10: NO | H10: =VLOOKUP(B10,Proveedores!$A$2:$D$11,3,FALSE) -> 0 | I10: =IF(G10="SI",F10*H10,0) -> 0 | J10: =A10+VLOOKUP(B10,Proveedores!$A$2:$D$11,4,FALSE) -> 45998
A11: 46013 | B11: Servicios Integrales Andinos SAC | C11: F03-000010 | D11: 1887.99 | E11: =D11*0.18 -> 339.8382 | F11: =D11+E11 -> 2227.8282 | G11: SI | H11: =VLOOKUP(B11,Proveedores!$A$2:$D$11,3,FALSE) -> 0.1 | I11: =IF(G11="SI",F11*H11,0) -> 222.78282 | J11: =A11+VLOOKUP(B11,Proveedores!$A$2:$D$11,4,FALSE) -> 46043
A12: 45986 | B12: Logística Sur SAC | C12: F03-000011 | D12: 1306.12 | E12: =D12*0.18 -> 235.1016 | F12: =D12+E12 -> 1541.2216 | G12: SI | H12: =VLOOKUP(B12,Proveedores!$A$2:$D$11,3,FALSE) -> 0.12 | I12: =IF(G12="SI",F12*H12,0) -> 184.94659 | J12: =A12+VLOOKUP(B12,Proveedores!$A$2:$D$11,4,FALSE) -> 46031
A13: 46018 | B13: Distribuidora Alfa SAC | C13: F03-000012 | D13: 953.01 | E13: =D13*0.18 -> 171.5418 | F13: =D13+E13 -> 1124.5518 | G13: NO | H13: =VLOOKUP(B13,Proveedores!$A$2:$D$11,3,FALSE) -> 0 | I13: =IF(G13="SI",F13*H13,0) -> 0 | J13: =A13+VLOOKUP(B13,Proveedores!$A$2:$D$11,4,FALSE) -> 46048
... A91: 45963 | B91: Suministros Empresariales SAC | C91: F03-000090 | D91: 3515.71 | E91: =D91*0.18 -> 632.8278 | F91: =D91+E91 -> 4148.5378 | G91: NO | H91: =VLOOKUP(B91,Proveedores!$A$2:$D$11,3,FALSE) -> 0 | I91: =IF(G91="SI",F91*H91,0) -> 0 | J91: =A91+VLOOKUP(B91,Proveedores!$A$2:$D$11,4,FALSE) -> 45993

Sheet Pagos
A1: NumFactura | B1: FechaPago | C1: MedioPago | D1: MontoPagado | E1: TotalFactura | F1: Saldo | G1: EstadoPago
A2: F01-000015 | B2: 46057 | C2: Efectivo | D2: =E2 -> 1859.2434 | E2: =VLOOKUP(A2,Facturas!$C$2:$F$91,4,FALSE) -> 1859.2434 | F2: =E2-D2 -> 0 | G2: =IF(F2<=0,"Pagado","Parcial") -> Pagado
A3: F01-000062 | B3: 46043 | C3: Depósito | D3: =E3 -> 3419.5338 | E3: =VLOOKUP(A3,Facturas!$C$2:$F$91,4,FALSE) -> 3419.5338 | F3: =E3-D3 -> 0 | G3: =IF(F3<=0,"Pagado","Parcial") -> Pagado
A4: F01-000006 | B4: 46017 | C4: Efectivo | D4: =E4 -> 3464.2794 | E4: =VLOOKUP(A4,Facturas!$C$2:$F$91,4,FALSE) -> 3464.2794 | F4: =E4-D4 -> 0 | G4: =IF(F4<=0,"Pagado","Parcial") -> Pagado
A5: F03-000067 | B5: 45992 | C5: Efectivo | D5: 1024.72 | E5: =VLOOKUP(A5,Facturas!$C$2:$F$91,4,FALSE) -> 494.538 | F5: =E5-D5 -> -530.182 | G5: =IF(F5<=0,"Pagado","Parcial") -> Pagado
A6: F01-000080 | B6: 46061 | C6: Efectivo | D6: =E6 -> 2950 | E6: =VLOOKUP(A6,Facturas!$C$2:$F$91,4,FALSE) -> 2950 | F6: =E6-D6 -> 0 | G6: =IF(F6<=0,"Pagado","Parcial") -> Pagado
A7: F03-000060 | B7: 46032 | C7: Efectivo | D7: =E7 -> 3297.4274 | E7: =VLOOKUP(A7,Facturas!$C$2:$F$91,4,FALSE) -> 3297.4274 | F7: =E7-D7 -> 0 | G7: =IF(F7<=0,"Pagado","Parcial") -> Pagado
A8: F01-000069 | B8: 45992 | C8: Transferencia | D8: 591.75 | E8: =VLOOKUP(A8,Facturas!$C$2:$F$91,4,FALSE) -> 1427.387 | F8: =E8-D8 -> 835.637 | G8: =IF(F8<=0,"Pagado","Parcial") -> Parcial
A9: F01-000058 | B9: 46054 | C9: Efectivo | D9: =E9 -> 1895.5638 | E9: =VLOOKUP(A9,Facturas!$C$2:$F$91,4,FALSE) -> 1895.5638 | F9: =E9-D9 -> 0 | G9: =IF(F9<=0,"Pagado","Parcial") -> Pagado
A10: F03-000016 | B10: 45984 | C10: Depósito | D10: =E10 -> 4198.7822 | E10: =VLOOKUP(A10,Facturas!$C$2:$F$91,4,FALSE) -> 4198.7822 | F10: =E10-D10 -> 0 | G10: =IF(F10<=0,"Pagado","Parcial") -> Pagado
A11: F01-000077 | B11: 46023 | C11: Efectivo | D11: 1314.17 | E11: =VLOOKUP(A11,Facturas!$C$2:$F$91,4,FALSE) -> 3396.5828 | F11: =E11-D11 -> 2082.4128 | G11: =IF(F11<=0,"Pagado","Parcial") -> Parcial
A12: F02-000018 | B12: 46008 | C12: Depósito | D12: 1249.69 | E12: =VLOOKUP(A12,Facturas!$C$2:$F$91,4,FALSE) -> 1445.2876 | F12: =E12-D12 -> 195.5976 | G12: =IF(F12<=0,"Pagado","Parcial") -> Parcial
A13: F03-000046 | B13: 45967 | C13: Transferencia | D13: =E13 -> 2936.8548 | E13: =VLOOKUP(A13,Facturas!$C$2:$F$91,4,FALSE) -> 2936.8548 | F13: =E13-D13 -> 0 | G13: =IF(F13<=0,"Pagado","Parcial") -> Pagado
A14: F01-000019 | B14: 46025 | C14: Transferencia | D14: =E14 -> 3157.857 | E14: =VLOOKUP(A14,Facturas!$C$2:$F$91,4,FALSE) -> 3157.857 | F14: =E14-D14 -> 0 | G14: =IF(F14<=0,"Pagado","Parcial") -> Pagado
A15: F01-000054 | B15: 46019 | C15: Efectivo | D15: =E15 -> 1480.7938 | E15: =VLOOKUP(A15,Facturas!$C$2:$F$91,4,FALSE) -> 1480.7938 | F15: =E15-D15 -> 0 | G15: =IF(F15<=0,"Pagado","Parcial") -> Pagado
A16: F01-000044 | B16: 46030 | C16: Transferencia | D16: =E16 -> 1258.3992 | E16: =VLOOKUP(A16,Facturas!$C$2:$F$91,4,FALSE) -> 1258.3992 | F16: =E16-D16 -> 0 | G16: =IF(F16<=0,"Pagado","Parcial") -> Pagado
A17: F03-000088 | B17: 46030 | C17: Depósito | D17: 943.43 | E17: =VLOOKUP(A17,Facturas!$C$2:$F$91,4,FALSE) -> 3425.7406 | F17: =E17-D17 -> 2482.3106 | G17: =IF(F17<=0,"Pagado","Parcial") -> Parcial
A18: F03-000084 | B18: 46056 | C18: Efectivo | D18: =E18 -> 479.198 | E18: =VLOOKUP(A18,Facturas!$C$2:$F$91,4,FALSE) -> 479.198 | F18: =E18-D18 -> 0 | G18: =IF(F18<=0,"Pagado","Parcial") -> Pagado
A19: F03-000068 | B19: 46037 | C19: Efectivo | D19: =E19 -> 2489.4932 | E19: =VLOOKUP(A19,Facturas!$C$2:$F$91,4,FALSE) -> 2489.4932 | F19: =E19-D19 -> 0 | G19: =IF(F19<=0,"Pagado","Parcial") -> Pagado
A20: F01-000027 | B20: 46002 | C20: Depósito | D20: =E20 -> 2921.7508 | E20: =VLOOKUP(A20,Facturas!$C$2:$F$91,4,FALSE) -> 2921.7508 | F20: =E20-D20 -> 0 | G20: =IF(F20<=0,"Pagado","Parcial") -> Pagado
A21: F03-000085 | B21: 46025 | C21: Depósito | D21: =E21 -> 942.0294 | E21: =VLOOKUP(A21,Facturas!$C$2:$F$91,4,FALSE) -> 942.0294 | F21: =E21-D21 -> 0 | G21: =IF(F21<=0,"Pagado","Parcial") -> Pagado
A22: F02-000051 | B22: 46019 | C22: Depósito | D22: 595.58 | E22: =VLOOKUP(A22,Facturas!$C$2:$F$91,4,FALSE) -> 2259.2162 | F22: =E22-D22 -> 1663.6362 | G22: =IF(F22<=0,"Pagado","Parcial") -> Parcial
A23: F02-000041 | B23: 46062 | C23: Depósito | D23: =E23 -> 4313.2186 | E23: =VLOOKUP(A23,Facturas!$C$2:$F$91,4,FALSE) -> 4313.2186 | F23: =E23-D23 -> 0 | G23: =IF(F23<=0,"Pagado","Parcial") -> Pagado
A24: F03-000010 | B24: 46051 | C24: Depósito | D24: =E24 -> 2227.8282 | E24: =VLOOKUP(A24,Facturas!$C$2:$F$91,4,FALSE) -> 2227.8282 | F24: =E24-D24 -> 0 | G24: =IF(F24<=0,"Pagado","Parcial") -> Pagado
A25: F01-000064 | B25: 46017 | C25: Depósito | D25: 657.17 | E25: =VLOOKUP(A25,Facturas!$C$2:$F$91,4,FALSE) -> 4298.4214 | F25: =E25-D25 -> 3641.2514 | G25: =IF(F25<=0,"Pagado","Parcial") -> Parcial
A26: F03-000074 | B26: 46037 | C26: Depósito | D26: =E26 -> 1579.7958 | E26: =VLOOKUP(A26,Facturas!$C$2:$F$91,4,FALSE) -> 1579.7958 | F26: =E26-D26 -> 0 | G26: =IF(F26<=0,"Pagado","Parcial") -> Pagado
A27: F03-000076 | B27: 46036 | C27: Transferencia | D27: 570.02 | E27: =VLOOKUP(A27,Facturas!$C$2:$F$91,4,FALSE) -> 758.209 | F27: =E27-D27 -> 188.189 | G27: =IF(F27<=0,"Pagado","Parcial") -> Parcial
A28: F01-000075 | B28: 46062 | C28: Transferencia | D28: =E28 -> 3088.6736 | E28: =VLOOKUP(A28,Facturas!$C$2:$F$91,4,FALSE) -> 3088.6736 | F28: =E28-D28 -> 0 | G28: =IF(F28<=0,"Pagado","Parcial") -> Pagado
A29: F01-000020 | B29: 46024 | C29: Depósito | D29: =E29 -> 3724.4458 | E29: =VLOOKUP(A29,Facturas!$C$2:$F$91,4,FALSE) -> 3724.4458 | F29: =E29-D29 -> 0 | G29: =IF(F29<=0,"Pagado","Parcial") -> Pagado
A30: F03-000011 | B30: 46025 | C30: Depósito | D30: =E30 -> 1541.2216 | E30: =VLOOKUP(A30,Facturas!$C$2:$F$91,4,FALSE) -> 1541.2216 | F30: =E30-D30 -> 0 | G30: =IF(F30<=0,"Pagado","Parcial") -> Pagado
A31: F01-000022 | B31: 46036 | C31: Depósito | D31: =E31 -> 3037.3672 | E31: =VLOOKUP(A31,Facturas!$C$2:$F$91,4,FALSE) -> 3037.3672 | F31: =E31-D31 -> 0 | G31: =IF(F31<=0,"Pagado","Parcial") -> Pagado
A32: F03-000031 | B32: 46038 | C32: Efectivo | D32: 1609.05 | E32: =VLOOKUP(A32,Facturas!$C$2:$F$91,4,FALSE) -> 1735.3198 | F32: =E32-D32 -> 126.2698 | G32: =IF(F32<=0,"Pagado","Parcial") -> Parcial
A33: F03-000083 | B33: 46048 | C33: Depósito | D33: =E33 -> 370.3312 | E33: =VLOOKUP(A33,Facturas!$C$2:$F$91,4,FALSE) -> 370.3312 | F33: =E33-D33 -> 0 | G33: =IF(F33<=0,"Pagado","Parcial") -> Pagado
A34: F01-000050 | B34: 46040 | C34: Depósito | D34: =E34 -> 719.9652 | E34: =VLOOKUP(A34,Facturas!$C$2:$F$91,4,FALSE) -> 719.9652 | F34: =E34-D34 -> 0 | G34: =IF(F34<=0,"Pagado","Parcial") -> Pagado
A35: F02-000024 | B35: 46028 | C35: Efectivo | D35: =E35 -> 3415.569 | E35: =VLOOKUP(A35,Facturas!$C$2:$F$91,4,FALSE) -> 3415.569 | F35: =E35-D35 -> 0 | G35: =IF(F35<=0,"Pagado","Parcial") -> Pagado
A36: F03-000042 | B36: 46049 | C36: Efectivo | D36: =E36 -> 1617.7918 | E36: =VLOOKUP(A36,Facturas!$C$2:$F$91,4,FALSE) -> 1617.7918 | F36: =E36-D36 -> 0 | G36: =IF(F36<=0,"Pagado","Parcial") -> Pagado
A37: F03-000087 | B37: 46011 | C37: Transferencia | D37: 977.03 | E37: =VLOOKUP(A37,Facturas!$C$2:$F$91,4,FALSE) -> 754.9404 | F37: =E37-D37 -> -222.0896 | G37: =IF(F37<=0,"Pagado","Parcial") -> Pagado
A38: F03-000034 | B38: 45997 | C38: Depósito | D38: =E38 -> 2427.0476 | E38: =VLOOKUP(A38,Facturas!$C$2:$F$91,4,FALSE) -> 2427.0476 | F38: =E38-D38 -> 0 | G38: =IF(F38<=0,"Pagado","Parcial") -> Pagado
A39: F01-000001 | B39: 46032 | C39: Efectivo | D39: 947.82 | E39: =VLOOKUP(A39,Facturas!$C$2:$F$91,4,FALSE) -> 3393.0074 | F39: =E39-D39 -> 2445.1874 | G39: =IF(F39<=0,"Pagado","Parcial") -> Parcial
A40: F01-000048 | B40: 46017 | C40: Efectivo | D40: =E40 -> 2557.4376 | E40: =VLOOKUP(A40,Facturas!$C$2:$F$91,4,FALSE) -> 2557.4376 | F40: =E40-D40 -> 0 | G40: =IF(F40<=0,"Pagado","Parcial") -> Pagado
...

Sheet Banco
A1: Fecha | B1: Descripción | C1: Cargo | D1: Abono
A2: 45963 | B2: Comisión bancaria | C2: 13.93
A3: 45967 | B3: Pago proveedor (F03-000046) | C3: =E13 -> 0
A4: 45978 | B4: Comisión bancaria | C4: 20.72
A5: 45984 | B5: Pago proveedor (F03-000016) | C5: =E10 -> 0
A6: 45989 | B6: Comisión bancaria | C6: 15.12
A7: 45991 | B7: Comisión bancaria | C7: 16.18
A8: 45992 | B8: Pago proveedor (F03-000067) | C8: 1024.72
A9: 45992 | B9: Pago proveedor (F01-000069) | C9: 591.75
A10: 45996 | B10: Pago proveedor (F03-000055) | C10: =E41 -> 0
A11: 45997 | B11: Pago proveedor (F03-000034) | C11: =E38 -> 0
A12: 46002 | B12: Pago proveedor (F01-000027) | C12: =E20 -> 0
A13: 46008 | B13: Pago proveedor (F02-000018) | C13: 1249.69
A14: 46011 | B14: Pago proveedor (F03-000087) | C14: 977.03
A15: 46016 | B15: Pago proveedor sin referencia | C15: 608.75
A16: 46017 | B16: Pago proveedor (F01-000006) | C16: =E4 -> 0
A17: 46017 | B17: Pago proveedor (F01-000064) | C17: 657.17
A18: 46017 | B18: Pago proveedor (F01-000048) | C18: =E40 -> 0
A19: 46019 | B19: Pago proveedor (F01-000054) | C19: =E15 -> 0
A20: 46019 | B20: Pago proveedor (F02-000051) | C20: 595.58
A21: 46023 | B21: Pago proveedor (F01-000077) | C21: 1314.17
A22: 46024 | B22: Pago proveedor (F01-000020) | C22: =E29 -> 0
A23: 46025 | B23: Pago proveedor (F01-000019) | C23: =E14 -> 0
A24: 46025 | B24: Pago proveedor (F03-000085) | C24: =E21 -> 0
A25: 46025 | B25: Pago proveedor (F03-000011) | C25: =E30 -> 0
A26: 46028 | B26: Pago proveedor (F02-000024) | C26: =E35 -> 0
A27: 46030 | B27: Pago proveedor (F01-000044) | C27: =E16 -> 0
A28: 46030 | B28: Pago proveedor (F03-000088) | C28: 943.43
A29: 46032 | B29: Pago proveedor (F03-000060) | C29: =E7 -> 0
A30: 46032 | B30: Pago proveedor (F01-000001) | C30: 947.82
A31: 46036 | B31: Pago proveedor (F03-000076) | C31: 570.02
A32: 46036 | B32: Pago proveedor (F01-000022) | C32: =E31 -> 0
A33: 46037 | B33: Pago proveedor (F03-000068) | C33: =E19 -> 0
A34: 46037 | B34: Pago proveedor (F03-000074) | C34: =E26 -> 0
A35: 46038 | B35: Pago proveedor (F03-000031) | C35: 1609.05
A36: 46040 | B36: Pago proveedor (F01-000050) | C36: =E34 -> 0
A37: 46043 | B37: Pago proveedor (F01-000062) | C37: =E3 -> 0
A38: 46048 | B38: Pago proveedor (F03-000083) | C38: =E33 -> 0
A39: 46049 | B39: Pago proveedor (F03-000042) | C39: =E36 -> 0
A40: 46051 | B40: Pago proveedor (F03-000010) | C40: =E24 -> 0
...

Sheet Conciliación
A1: FechaBanco | B1: DescripciónBanco | C1: Cargo | D1: MatchPago | E1: NumFactura | F1: Observación
A2: =Banco!A2 -> 45963 | B2: =Banco!B2 -> Comisión bancaria | C2: =Banco!C2 -> 13.93 | D2: =IF(ISNUMBER(MATCH(C2,Pagos!$D$2:$D$41,0)),"SI","NO") -> NO | E2: =IF(D2="SI",INDEX(Pagos!$A$2:$A$41,MATCH(C2,Pagos!$D$2:$D$41,0)),"") | F2: =IF(B2="Comisión bancaria","Comisión","" & IF(D2="SI","Pago conciliado","Revisar")) -> Comisión
A3: =Banco!A3 -> 45967 | B3: =Banco!B3 -> Pago proveedor (F03-000046) | C3: =Banco!C3 -> 0 | D3: =IF(ISNUMBER(MATCH(C3,Pagos!$D$2:$D$41,0)),"SI","NO") -> NO | E3: =IF(D3="SI",INDEX(Pagos!$A$2:$A$41,MATCH(C3,Pagos!$D$2:$D$41,0)),"") | F3: =IF(B3="Comisión bancaria","Comisión","" & IF(D3="SI","Pago conciliado","Revisar")) -> Revisar
A4: =Banco!A4 -> 45978 | B4: =Banco!B4 -> Comisión bancaria | C4: =Banco!C4 -> 20.72 | D4: =IF(ISNUMBER(MATCH(C4,Pagos!$D$2:$D$41,0)),"SI","NO") -> NO | E4: =IF(D4="SI",INDEX(Pagos!$A$2:$A$41,MATCH(C4,Pagos!$D$2:$D$41,0)),"") | F4: =IF(B4="Comisión bancaria","Comisión","" & IF(D4="SI","Pago conciliado","Revisar")) -> Comisión
A5: =Banco!A5 -> 45984 | B5: =Banco!B5 -> Pago proveedor (F03-000016) | C5: =Banco!C5 -> 0 | D5: =IF(ISNUMBER(MATCH(C5,Pagos!$D$2:$D$41,0)),"SI","NO") -> NO | E5: =IF(D5="SI",INDEX(Pagos!$A$2:$A$41,MATCH(C5,Pagos!$D$2:$D$41,0)),"") | F5: =IF(B5="Comisión bancaria","Comisión","" & IF(D5="SI","Pago conciliado","Revisar")) -> Revisar
A6: =Banco!A6 -> 45989 | B6: =Banco!B6 -> Comisión bancaria | C6: =Banco!C6 -> 15.12 | D6: =IF(ISNUMBER(MATCH(C6,Pagos!$D$2:$D$41,0)),"SI","NO") -> NO | E6: =IF(D6="SI",INDEX(Pagos!$A$2:$A$41,MATCH(C6,Pagos!$D$2:$D$41,0)),"") | F6: =IF(B6="Comisión bancaria","Comisión","" & IF(D6="SI","Pago conciliado","Revisar")) -> Comisión
A7: =Banco!A7 -> 45991 | B7: =Banco!B7 -> Comisión bancaria | C7: =Banco!C7 -> 16.18 | D7: =IF(ISNUMBER(MATCH(C7,Pagos!$D$2:$D$41,0)),"SI","NO") -> NO | E7: =IF(D7="SI",INDEX(Pagos!$A$2:$A$41,MATCH(C7,Pagos!$D$2:$D$41,0)),"") | F7: =IF(B7="Comisión bancaria","Comisión","" & IF(D7="SI","Pago conciliado","Revisar")) -> Comisión
A8: =Banco!A8 -> 45992 | B8: =Banco!B8 -> Pago proveedor (F03-000067) | C8: =Banco!C8 -> 1024.72 | D8: =IF(ISNUMBER(MATCH(C8,Pagos!$D$2:$D$41,0)),"SI","NO") -> SI | E8: =IF(D8="SI",INDEX(Pagos!$A$2:$A$41,MATCH(C8,Pagos!$D$2:$D$41,0)),"") -> F03-000067 | F8: =IF(B8="Comisión bancaria","Comisión","" & IF(D8="SI","Pago conciliado","Revisar")) -> Pago conciliado
A9: =Banco!A9 -> 45992 | B9: =Banco!B9 -> Pago proveedor (F01-000069) | C9: =Banco!C9 -> 591.75 | D9: =IF(ISNUMBER(MATCH(C9,Pagos!$D$2:$D$41,0)),"SI","NO") -> SI | E9: =IF(D9="SI",INDEX(Pagos!$A$2:$A$41,MATCH(C9,Pagos!$D$2:$D$41,0)),"") -> F01-000069 | F9: =IF(B9="Comisión bancaria","Comisión","" & IF(D9="SI","Pago conciliado","Revisar")) -> Pago conciliado
A10: =Banco!A10 -> 45996 | B10: =Banco!B10 -> Pago proveedor (F03-000055) | C10: =Banco!C10 -> 0 | D10: =IF(ISNUMBER(MATCH(C10,Pagos!$D$2:$D$41,0)),"SI","NO") -> NO | E10: =IF(D10="SI",INDEX(Pagos!$A$2:$A$41,MATCH(C10,Pagos!$D$2:$D$41,0)),"") | F10: =IF(B10="Comisión bancaria","Comisión","" & IF(D10="SI","Pago conciliado","Revisar")) -> Revisar
A11: =Banco!A11 -> 45997 | B11: =Banco!B11 -> Pago proveedor (F03-000034) | C11: =Banco!C11 -> 0 | D11: =IF(ISNUMBER(MATCH(C11,Pagos!$D$2:$D$41,0)),"SI","NO") -> NO | E11: =IF(D11="SI",INDEX(Pagos!$A$2:$A$41,MATCH(C11,Pagos!$D$2:$D$41,0)),"") | F11: =IF(B11="Comisión bancaria","Comisión","" & IF(D11="SI","Pago conciliado","Revisar")) -> Revisar
A12: =Banco!A12 -> 46002 | B12: =Banco!B12 -> Pago proveedor (F01-000027) | C12: =Banco!C12 -> 0 | D12: =IF(ISNUMBER(MATCH(C12,Pagos!$D$2:$D$41,0)),"SI","NO") -> NO | E12: =IF(D12="SI",INDEX(Pagos!$A$2:$A$41,MATCH(C12,Pagos!$D$2:$D$41,0)),"") | F12: =IF(B12="Comisión bancaria","Comisión","" & IF(D12="SI","Pago conciliado","Revisar")) -> Revisar
A13: =Banco!A13 -> 46008 | B13: =Banco!B13 -> Pago proveedor (F02-000018) | C13: =Banco!C13 -> 1249.69 | D13: =IF(ISNUMBER(MATCH(C13,Pagos!$D$2:$D$41,0)),"SI","NO") -> SI | E13: =IF(D13="SI",INDEX(Pagos!$A$2:$A$41,MATCH(C13,Pagos!$D$2:$D$41,0)),"") -> F02-000018 | F13: =IF(B13="Comisión bancaria","Comisión","" & IF(D13="SI","Pago conciliado","Revisar")) -> Pago conciliado
... A46: =Banco!A46 -> 46062 | B46: =Banco!B46 -> Pago proveedor (F01-000075) | C46: =Banco!C46 -> 0 | D46: =IF(ISNUMBER(MATCH(C46,Pagos!$D$2:$D$41,0)),"SI","NO") -> NO | E46: =IF(D46="SI",INDEX(Pagos!$A$2:$A$41,MATCH(C46,Pagos!$D$2:$D$41,0)),"") | F46: =IF(B46="Comisión bancaria","Comisión","" & IF(D46="SI","Pago conciliado","Revisar")) -> Revisar

Sheet Reportes
A1: KPIs
A3: Total facturas (S/) | B3: =SUM(Facturas!F2:F91) -> 203522.72
A4: Total cuentas por pagar (S/) | B4: =B3-SUM(Pagos!D2:D41) -> 124935.63
A5: Facturas vencidas (conteo) | B5: =COUNTIF(Facturas!J2:J91,"<"&TODAY()) -> 42
A6: Pagos realizados (S/) | B6: =SUM(Pagos!D2:D41) -> 78587.092
A7: Detracciones estimadas (S/) | B7: =SUM(Facturas!I2:I91) -> 7220.5753
A12: Estado de Facturas | B12: Facturas
A13: NO | B13: 56
A14: SI | B14: 34
A15: Total general | B15: 90
A19: Monto por proveedor | B19: Total de proveedor
A20: Soluciones Informáticas SAC | B20: 31720.005
A21: Servicios Integrales Andinos SAC | B21: 30535.391
A22: Logística Sur SAC | B22: 27356.884
A23: Suministros Empresariales SAC | B23: 25449.921
A24: Seguridad Integral Omega SAC | B24: 20209.235
A25: Distribuidora Alfa SAC | B25: 20047.079
A26: Mantenimiento Técnico Perú SAC | B26: 18339.277
A27: Transportes Lima Express SAC | B27: 12508.932
A28: Servicios Generales Beta SAC | B28: 11027.914
A29: Consultoría Delta SRL | B29: 6328.0804
A30: Total general | B30: 203522.72
A34: FechaVencimiento | B34: (Todas)
A36: Etiquetas de fila | B36: Cuenta de NumFactura
A37: 2025 | B37: 48
A38: 2026 | B38: 42
A39: Total general | B39: 90
A42: Facturas | C42: Pagos
A43: 203522.72 | C43: 78587.092
A46: Concepto | B46: Monto
A47: Facturado | B47: =+GETPIVOTDATA("Total",$A$42) -> 203522.72
A48: Pagado | B48: =+GETPIVOTDATA("MontoPagado",$C$42) -> 78587.092

Sheet Dashboard
